[2023-12-20T20:44:29.781+0000] {taskinstance.py:1159} INFO - Dependencies all met for dep_context=non-requeueable deps ti=<TaskInstance: bitkub_dag.complete_Bitkub_etl scheduled__2021-12-15T00:00:00+00:00 [queued]>
[2023-12-20T20:44:29.797+0000] {taskinstance.py:1159} INFO - Dependencies all met for dep_context=requeueable deps ti=<TaskInstance: bitkub_dag.complete_Bitkub_etl scheduled__2021-12-15T00:00:00+00:00 [queued]>
[2023-12-20T20:44:29.797+0000] {taskinstance.py:1361} INFO - Starting attempt 2 of 2
[2023-12-20T20:44:29.942+0000] {taskinstance.py:1382} INFO - Executing <Task(PythonOperator): complete_Bitkub_etl> on 2021-12-15 00:00:00+00:00
[2023-12-20T20:44:29.948+0000] {standard_task_runner.py:57} INFO - Started process 2643 to run task
[2023-12-20T20:44:29.953+0000] {standard_task_runner.py:84} INFO - Running: ['airflow', 'tasks', 'run', 'bitkub_dag', 'complete_Bitkub_etl', 'scheduled__2021-12-15T00:00:00+00:00', '--job-id', '836', '--raw', '--subdir', 'DAGS_FOLDER/bitkub_dag.py', '--cfg-path', '/tmp/tmp31ddgdjr']
[2023-12-20T20:44:29.953+0000] {standard_task_runner.py:85} INFO - Job 836: Subtask complete_Bitkub_etl
[2023-12-20T20:44:29.993+0000] {task_command.py:416} INFO - Running <TaskInstance: bitkub_dag.complete_Bitkub_etl scheduled__2021-12-15T00:00:00+00:00 [running]> on host ip-172-31-6-101.ca-central-1.compute.internal
[2023-12-20T20:44:30.053+0000] {taskinstance.py:1662} INFO - Exporting env vars: AIRFLOW_CTX_DAG_EMAIL='airflow@example.com' AIRFLOW_CTX_DAG_OWNER='airflow' AIRFLOW_CTX_DAG_ID='bitkub_dag' AIRFLOW_CTX_TASK_ID='complete_Bitkub_etl' AIRFLOW_CTX_EXECUTION_DATE='2021-12-15T00:00:00+00:00' AIRFLOW_CTX_TRY_NUMBER='2' AIRFLOW_CTX_DAG_RUN_ID='scheduled__2021-12-15T00:00:00+00:00'
[2023-12-20T20:44:31.127+0000] {taskinstance.py:1937} ERROR - Task failed with exception
Traceback (most recent call last):
  File "/usr/local/lib/python3.10/dist-packages/s3fs/core.py", line 113, in _error_wrapper
    return await func(*args, **kwargs)
  File "/usr/local/lib/python3.10/dist-packages/aiobotocore/client.py", line 408, in _make_api_call
    raise error_class(parsed_response, operation_name)
botocore.exceptions.ClientError: An error occurred (AccessDenied) when calling the PutObject operation: Access Denied

The above exception was the direct cause of the following exception:

Traceback (most recent call last):
  File "/usr/local/lib/python3.10/dist-packages/airflow/operators/python.py", line 192, in execute
    return_value = self.execute_callable()
  File "/usr/local/lib/python3.10/dist-packages/airflow/operators/python.py", line 209, in execute_callable
    return self.python_callable(*self.op_args, **self.op_kwargs)
  File "/home/ubuntu/airflow/bitkub_dag/bitkub_etl.py", line 60, in Bitkub_etl
    df.to_csv('s3://mybitkub-etl/Bitkub.csv')
  File "/usr/local/lib/python3.10/dist-packages/pandas/core/generic.py", line 3902, in to_csv
    return DataFrameRenderer(formatter).to_csv(
  File "/usr/local/lib/python3.10/dist-packages/pandas/io/formats/format.py", line 1152, in to_csv
    csv_formatter.save()
  File "/usr/local/lib/python3.10/dist-packages/pandas/io/formats/csvs.py", line 247, in save
    with get_handle(
  File "/usr/local/lib/python3.10/dist-packages/pandas/io/common.py", line 142, in __exit__
    self.close()
  File "/usr/local/lib/python3.10/dist-packages/pandas/io/common.py", line 134, in close
    handle.close()
  File "/usr/local/lib/python3.10/dist-packages/fsspec/spec.py", line 1930, in close
    self.flush(force=True)
  File "/usr/local/lib/python3.10/dist-packages/fsspec/spec.py", line 1801, in flush
    if self._upload_chunk(final=force) is not False:
  File "/usr/local/lib/python3.10/dist-packages/s3fs/core.py", line 2299, in _upload_chunk
    self.commit()
  File "/usr/local/lib/python3.10/dist-packages/s3fs/core.py", line 2317, in commit
    write_result = self._call_s3("put_object", **kw)
  File "/usr/local/lib/python3.10/dist-packages/s3fs/core.py", line 2162, in _call_s3
    return self.fs.call_s3(method, self.s3_additional_kwargs, *kwarglist, **kwargs)
  File "/usr/local/lib/python3.10/dist-packages/fsspec/asyn.py", line 118, in wrapper
    return sync(self.loop, func, *args, **kwargs)
  File "/usr/local/lib/python3.10/dist-packages/fsspec/asyn.py", line 103, in sync
    raise return_result
  File "/usr/local/lib/python3.10/dist-packages/fsspec/asyn.py", line 56, in _runner
    result[0] = await coro
  File "/usr/local/lib/python3.10/dist-packages/s3fs/core.py", line 348, in _call_s3
    return await _error_wrapper(
  File "/usr/local/lib/python3.10/dist-packages/s3fs/core.py", line 140, in _error_wrapper
    raise err
PermissionError: Access Denied
[2023-12-20T20:44:31.140+0000] {taskinstance.py:1400} INFO - Marking task as FAILED. dag_id=bitkub_dag, task_id=complete_Bitkub_etl, execution_date=20211215T000000, start_date=20231220T204429, end_date=20231220T204431
[2023-12-20T20:44:31.160+0000] {standard_task_runner.py:104} ERROR - Failed to execute job 836 for task complete_Bitkub_etl (Access Denied; 2643)
[2023-12-20T20:44:31.173+0000] {local_task_job_runner.py:228} INFO - Task exited with return code 1
[2023-12-20T20:44:31.202+0000] {taskinstance.py:2778} INFO - 0 downstream tasks scheduled from follow-on schedule check
