[2023-12-18T01:26:53.640+0000] {taskinstance.py:1159} INFO - Dependencies all met for dep_context=non-requeueable deps ti=<TaskInstance: bitkub_dag.complete_Bitkub_etl scheduled__2020-11-14T00:00:00+00:00 [queued]>
[2023-12-18T01:26:53.645+0000] {taskinstance.py:1159} INFO - Dependencies all met for dep_context=requeueable deps ti=<TaskInstance: bitkub_dag.complete_Bitkub_etl scheduled__2020-11-14T00:00:00+00:00 [queued]>
[2023-12-18T01:26:53.645+0000] {taskinstance.py:1361} INFO - Starting attempt 4 of 4
[2023-12-18T01:26:53.660+0000] {taskinstance.py:1382} INFO - Executing <Task(PythonOperator): complete_Bitkub_etl> on 2020-11-14 00:00:00+00:00
[2023-12-18T01:26:53.664+0000] {standard_task_runner.py:57} INFO - Started process 5617 to run task
[2023-12-18T01:26:53.668+0000] {standard_task_runner.py:84} INFO - Running: ['airflow', 'tasks', 'run', 'bitkub_dag', 'complete_Bitkub_etl', 'scheduled__2020-11-14T00:00:00+00:00', '--job-id', '170', '--raw', '--subdir', 'DAGS_FOLDER/bitkub_dag.py', '--cfg-path', '/tmp/tmpmk2o8vy2']
[2023-12-18T01:26:53.669+0000] {standard_task_runner.py:85} INFO - Job 170: Subtask complete_Bitkub_etl
[2023-12-18T01:26:53.710+0000] {task_command.py:416} INFO - Running <TaskInstance: bitkub_dag.complete_Bitkub_etl scheduled__2020-11-14T00:00:00+00:00 [running]> on host ip-172-31-6-101.ca-central-1.compute.internal
[2023-12-18T01:26:53.767+0000] {taskinstance.py:1662} INFO - Exporting env vars: AIRFLOW_CTX_DAG_EMAIL='airflow@example.com' AIRFLOW_CTX_DAG_OWNER='airflow' AIRFLOW_CTX_DAG_ID='bitkub_dag' AIRFLOW_CTX_TASK_ID='complete_Bitkub_etl' AIRFLOW_CTX_EXECUTION_DATE='2020-11-14T00:00:00+00:00' AIRFLOW_CTX_TRY_NUMBER='4' AIRFLOW_CTX_DAG_RUN_ID='scheduled__2020-11-14T00:00:00+00:00'
[2023-12-18T01:26:53.768+0000] {taskinstance.py:1937} ERROR - Task failed with exception
Traceback (most recent call last):
  File "/usr/local/lib/python3.10/dist-packages/airflow/operators/python.py", line 192, in execute
    return_value = self.execute_callable()
  File "/usr/local/lib/python3.10/dist-packages/airflow/operators/python.py", line 209, in execute_callable
    return self.python_callable(*self.op_args, **self.op_kwargs)
  File "/home/ubuntu/airflow/bitkub_dag/bitkub_etl.py", line 55, in Bitkub_etl
    list_btc=[data_json]
UnboundLocalError: local variable 'data_json' referenced before assignment
[2023-12-18T01:26:53.772+0000] {taskinstance.py:1400} INFO - Marking task as FAILED. dag_id=bitkub_dag, task_id=complete_Bitkub_etl, execution_date=20201114T000000, start_date=20231218T012653, end_date=20231218T012653
[2023-12-18T01:26:53.783+0000] {standard_task_runner.py:104} ERROR - Failed to execute job 170 for task complete_Bitkub_etl (local variable 'data_json' referenced before assignment; 5617)
[2023-12-18T01:26:53.800+0000] {local_task_job_runner.py:228} INFO - Task exited with return code 1
[2023-12-18T01:26:53.812+0000] {taskinstance.py:2778} INFO - 0 downstream tasks scheduled from follow-on schedule check
