[2023-12-18T01:43:55.823+0000] {taskinstance.py:1159} INFO - Dependencies all met for dep_context=non-requeueable deps ti=<TaskInstance: bitkub_dag.complete_Bitkub_etl scheduled__2021-02-04T00:00:00+00:00 [queued]>
[2023-12-18T01:43:55.955+0000] {taskinstance.py:1159} INFO - Dependencies all met for dep_context=requeueable deps ti=<TaskInstance: bitkub_dag.complete_Bitkub_etl scheduled__2021-02-04T00:00:00+00:00 [queued]>
[2023-12-18T01:43:55.956+0000] {taskinstance.py:1361} INFO - Starting attempt 1 of 2
[2023-12-18T01:43:55.972+0000] {taskinstance.py:1382} INFO - Executing <Task(PythonOperator): complete_Bitkub_etl> on 2021-02-04 00:00:00+00:00
[2023-12-18T01:43:55.977+0000] {standard_task_runner.py:57} INFO - Started process 1498 to run task
[2023-12-18T01:43:55.982+0000] {standard_task_runner.py:84} INFO - Running: ['airflow', 'tasks', 'run', 'bitkub_dag', 'complete_Bitkub_etl', 'scheduled__2021-02-04T00:00:00+00:00', '--job-id', '333', '--raw', '--subdir', 'DAGS_FOLDER/bitkub_dag.py', '--cfg-path', '/tmp/tmp22q_zmbb']
[2023-12-18T01:43:55.982+0000] {standard_task_runner.py:85} INFO - Job 333: Subtask complete_Bitkub_etl
[2023-12-18T01:43:56.042+0000] {task_command.py:416} INFO - Running <TaskInstance: bitkub_dag.complete_Bitkub_etl scheduled__2021-02-04T00:00:00+00:00 [running]> on host ip-172-31-6-101.ca-central-1.compute.internal
[2023-12-18T01:43:56.101+0000] {taskinstance.py:1662} INFO - Exporting env vars: AIRFLOW_CTX_DAG_EMAIL='airflow@example.com' AIRFLOW_CTX_DAG_OWNER='airflow' AIRFLOW_CTX_DAG_ID='bitkub_dag' AIRFLOW_CTX_TASK_ID='complete_Bitkub_etl' AIRFLOW_CTX_EXECUTION_DATE='2021-02-04T00:00:00+00:00' AIRFLOW_CTX_TRY_NUMBER='1' AIRFLOW_CTX_DAG_RUN_ID='scheduled__2021-02-04T00:00:00+00:00'
[2023-12-18T01:43:56.103+0000] {taskinstance.py:1937} ERROR - Task failed with exception
Traceback (most recent call last):
  File "/usr/local/lib/python3.10/dist-packages/airflow/operators/python.py", line 192, in execute
    return_value = self.execute_callable()
  File "/usr/local/lib/python3.10/dist-packages/airflow/operators/python.py", line 209, in execute_callable
    return self.python_callable(*self.op_args, **self.op_kwargs)
  File "/home/ubuntu/airflow/bitkub_dag/bitkub_etl.py", line 55, in Bitkub_etl
    list_btc=[data_json]
UnboundLocalError: local variable 'data_json' referenced before assignment
[2023-12-18T01:43:56.106+0000] {taskinstance.py:1400} INFO - Marking task as UP_FOR_RETRY. dag_id=bitkub_dag, task_id=complete_Bitkub_etl, execution_date=20210204T000000, start_date=20231218T014355, end_date=20231218T014356
[2023-12-18T01:43:56.126+0000] {standard_task_runner.py:104} ERROR - Failed to execute job 333 for task complete_Bitkub_etl (local variable 'data_json' referenced before assignment; 1498)
[2023-12-18T01:43:56.154+0000] {local_task_job_runner.py:228} INFO - Task exited with return code 1
[2023-12-18T01:43:56.170+0000] {taskinstance.py:2778} INFO - 0 downstream tasks scheduled from follow-on schedule check
